Workbook

Sheet Dahsboard

Sheet Master Kode
B2: Kode | C2: Nama Barang | D2: Harga per Kg | F2: Kode | G2: Customer
B3: BP001 | C3: PET Clear Flakes | D3: 12500 | F3: PT001 | G3: PT Bintang Daur Ulang
B4: BP002 | C4: PET Blue Flakes | D4: 10000 | F4: PT002 | G4: PT Cahaya Plastik Abadi
B5: BP003 | C5: HDPE Natural Flakes | D5: 13500 | F5: PT003 | G5: PT Global Recycle Industry
B6: BP004 | C6: HDPE Mixed Color Flakes | D6: 9500 | F6: PT004 | G6: PT Indo Plastik Mandiri
B7: BP005 | C7: PP Injection Flakes | D7: 11000 | F7: PT005 | G7: PT Maju Jaya Plastik
B8: BP006 | C8: PET Green Flakes | D8: 9000 | F8: PT006 | G8: PT Mitra Plastik Nusantara
B9: BP007 | C9: HDPE Blue Drum Flakes | D9: 11500 | F9: PT007 | G9: PT Surya Polimer Indonesia
B10: BP008 | C10: PET Mixed Color Flakes | D10: 8500
B11: BP009 | C11: PP White Flakes | D11: 12000
B12: BP010 | C12: HDPE Bottle Cap Flakes | D12: 10500
B13: BP011 | C13: PET Hot Washed Flakes | D13: 14500

Sheet Purchase Order
B2: Tanggal Input | C2: Kode PO | D2: Nama Klien | E2: Kode Barang | F2: Nama Barang | G2: Qty | H2: Satuan | I2: Tanggal Pengiriman
B3: 45653 | C3: PO01012501 | D3: PT Maju Jaya Plastik | E3: BP001 | F3: =VLOOKUP(E3,'Master Kode'!$B$3:$D$13,2,0) -> PET Clear Flakes | G3: 1205 | H3: kg | I3: 45660
B4: 45653 | C4: PO01012502 | D4: PT Surya Polimer Indonesia | E4: BP002 | F4: =VLOOKUP(E4,'Master Kode'!$B$3:$D$13,2,0) -> PET Blue Flakes | G4: 3015 | H4: kg | I4: 45661
B5: 45654 | C5: PO02012501 | D5: PT Mitra Plastik Nusantara | E5: BP003 | F5: =VLOOKUP(E5,'Master Kode'!$B$3:$D$13,2,0) -> HDPE Natural Flakes | G5: 2150 | H5: kg | I5: 45662
B6: 45654 | C6: PO02012502 | D6: PT Global Recycle Industry | E6: BP004 | F6: =VLOOKUP(E6,'Master Kode'!$B$3:$D$13,2,0) -> HDPE Mixed Color Flakes | G6: 1890 | H6: kg | I6: 45662
B7: 45655 | C7: PO03012501 | D7: PT Indo Plastik Mandiri | E7: BP005 | F7: =VLOOKUP(E7,'Master Kode'!$B$3:$D$13,2,0) -> PP Injection Flakes | G7: 2750 | H7: kg | I7: 45663
B8: 45655 | C8: PO03012502 | D8: PT Cahaya Plastik Abadi | E8: BP006 | F8: =VLOOKUP(E8,'Master Kode'!$B$3:$D$13,2,0) -> PET Green Flakes | G8: 3320 | H8: kg | I8: 45664
B9: 45656 | C9: PO04012501 | D9: PT Bintang Daur Ulang | E9: BP007 | F9: =VLOOKUP(E9,'Master Kode'!$B$3:$D$13,2,0) -> HDPE Blue Drum Flakes | G9: 1450 | H9: kg | I9: 45664
B10: 45656 | C10: PO04012502 | D10: PT Maju Jaya Plastik | E10: BP008 | F10: =VLOOKUP(E10,'Master Kode'!$B$3:$D$13,2,0) -> PET Mixed Color Flakes | G10: 2100 | H10: kg | I10: 45665
B11: 45657 | C11: PO05012501 | D11: PT Surya Polimer Indonesia | E11: BP009 | F11: =VLOOKUP(E11,'Master Kode'!$B$3:$D$13,2,0) -> PP White Flakes | G11: 3980 | H11: kg | I11: 45666
B12: 45658 | C12: PO06012501 | D12: PT Mitra Plastik Nusantara | E12: BP010 | F12: =VLOOKUP(E12,'Master Kode'!$B$3:$D$13,2,0) -> HDPE Bottle Cap Flakes | G12: 2560 | H12: kg | I12: 45667
B13: 45659 | C13: PO07012501 | D13: PT Global Recycle Industry | E13: BP011 | F13: =VLOOKUP(E13,'Master Kode'!$B$3:$D$13,2,0) -> PET Hot Washed Flakes | G13: 3175 | H13: kg | I13: 45668
B14: 45660 | C14: PO08012501 | D14: PT Indo Plastik Mandiri | E14: BP001 | F14: =VLOOKUP(E14,'Master Kode'!$B$3:$D$13,2,0) -> PET Clear Flakes | G14: 1875 | H14: kg | I14: 45669
... B313: 46006 | C313: PO20122501 | D313: PT Cahaya Plastik Abadi | E313: BP005 | F313: =VLOOKUP(E313,'Master Kode'!$B$3:$D$13,2,0) -> PP Injection Flakes | G313: 2750 | H313: kg | I313: 46014

Sheet Delivery Order
B2: No DO | C2: Tanggal DO | D2: No PO | E2: Nama Klien | F2: Kode Barang | G2: Nama Barang | H2: Qty | I2: Satuan
B3: DO030125001 | C3: =DATE(2000+MID(B3,7,2),MID(B3,5,2),MID(B3,3,2)) -> 45660 | D3: PO01012501 | E3: PT Maju Jaya Plastik | F3: BP001 | G3: =VLOOKUP(F3,'Master Kode'!$B$3:$D$13,2,0) -> PET Clear Flakes | H3: 1205 | I3: kg
B4: DO040125002 | C4: =DATE(2000+MID(B4,7,2),MID(B4,5,2),MID(B4,3,2)) -> 45661 | D4: PO01012502 | E4: PT Surya Polimer Indonesia | F4: BP002 | G4: =VLOOKUP(F4,'Master Kode'!$B$3:$D$13,2,0) -> PET Blue Flakes | H4: 3015 | I4: kg
B5: DO050125003 | C5: =DATE(2000+MID(B5,7,2),MID(B5,5,2),MID(B5,3,2)) -> 45662 | D5: PO02012501 | E5: PT Mitra Plastik Nusantara | F5: BP003 | G5: =VLOOKUP(F5,'Master Kode'!$B$3:$D$13,2,0) -> HDPE Natural Flakes | H5: 2150 | I5: kg
B6: DO050125004 | C6: =DATE(2000+MID(B6,7,2),MID(B6,5,2),MID(B6,3,2)) -> 45662 | D6: PO02012502 | E6: PT Global Recycle Industry | F6: BP004 | G6: =VLOOKUP(F6,'Master Kode'!$B$3:$D$13,2,0) -> HDPE Mixed Color Flakes | H6: 1890 | I6: kg
B7: DO060125005 | C7: =DATE(2000+MID(B7,7,2),MID(B7,5,2),MID(B7,3,2)) -> 45663 | D7: PO03012501 | E7: PT Indo Plastik Mandiri | F7: BP005 | G7: =VLOOKUP(F7,'Master Kode'!$B$3:$D$13,2,0) -> PP Injection Flakes | H7: 2750 | I7: kg
B8: DO070125006 | C8: =DATE(2000+MID(B8,7,2),MID(B8,5,2),MID(B8,3,2)) -> 45664 | D8: PO03012502 | E8: PT Cahaya Plastik Abadi | F8: BP006 | G8: =VLOOKUP(F8,'Master Kode'!$B$3:$D$13,2,0) -> PET Green Flakes | H8: 3320 | I8: kg
B9: DO070125007 | C9: =DATE(2000+MID(B9,7,2),MID(B9,5,2),MID(B9,3,2)) -> 45664 | D9: PO04012501 | E9: PT Bintang Daur Ulang | F9: BP007 | G9: =VLOOKUP(F9,'Master Kode'!$B$3:$D$13,2,0) -> HDPE Blue Drum Flakes | H9: 1450 | I9: kg
B10: DO080125008 | C10: =DATE(2000+MID(B10,7,2),MID(B10,5,2),MID(B10,3,2)) -> 45665 | D10: PO04012502 | E10: PT Maju Jaya Plastik | F10: BP008 | G10: =VLOOKUP(F10,'Master Kode'!$B$3:$D$13,2,0) -> PET Mixed Color Flakes | H10: 2100 | I10: kg
B11: DO090125009 | C11: =DATE(2000+MID(B11,7,2),MID(B11,5,2),MID(B11,3,2)) -> 45666 | D11: PO05012501 | E11: PT Surya Polimer Indonesia | F11: BP009 | G11: =VLOOKUP(F11,'Master Kode'!$B$3:$D$13,2,0) -> PP White Flakes | H11: 3980 | I11: kg
B12: DO100125010 | C12: =DATE(2000+MID(B12,7,2),MID(B12,5,2),MID(B12,3,2)) -> 45667 | D12: PO06012501 | E12: PT Mitra Plastik Nusantara | F12: BP010 | G12: =VLOOKUP(F12,'Master Kode'!$B$3:$D$13,2,0) -> HDPE Bottle Cap Flakes | H12: 2560 | I12: kg
B13: DO110125011 | C13: =DATE(2000+MID(B13,7,2),MID(B13,5,2),MID(B13,3,2)) -> 45668 | D13: PO07012501 | E13: PT Global Recycle Industry | F13: BP011 | G13: =VLOOKUP(F13,'Master Kode'!$B$3:$D$13,2,0) -> PET Hot Washed Flakes | H13: 3175 | I13: kg
B14: DO120125012 | C14: =DATE(2000+MID(B14,7,2),MID(B14,5,2),MID(B14,3,2)) -> 45669 | D14: PO08012501 | E14: PT Indo Plastik Mandiri | F14: BP001 | G14: =VLOOKUP(F14,'Master Kode'!$B$3:$D$13,2,0) -> PET Clear Flakes | H14: 1875 | I14: kg
... B313: DO231225027 | C313: =DATE(2000+MID(B313,7,2),MID(B313,5,2),MID(B313,3,2)) -> 46014 | D313: PO20122501 | E313: PT Cahaya Plastik Abadi | F313: BP005 | G313: =VLOOKUP(F313,'Master Kode'!$B$3:$D$13,2,0) -> PP Injection Flakes | H313: 2750 | I313: kg

Sheet Invoice
B2: No Invoice | C2: Tanggal Invoice | D2: No DO | E2: No PO | F2: Nama Klien | G2: Kode Produk | H2: Nama Produk | I2: Qty | J2: Satuan | K2: Harga/kg (Rp) | L2: Total (Rp) | N2: Kode | O2: Customer | P2: Qty (Kg) | Q2: %
B3: INV030125001 | C3: =DATE(2000+MID(B3,8,2),MID(B3,6,2),MID(B3,4,2)) -> 45660 | D3: DO030125001 | E3: PO01012501 | F3: PT Maju Jaya Plastik | G3: BP001 | H3: =VLOOKUP(G3,'Master Kode'!$B$3:$D$13,2,0) -> PET Clear Flakes | I3: 1205 | J3: kg | K3: =VLOOKUP(G3,'Master Kode'!$B$3:$D$13,3,0) -> 12500 | L3: =K3*I3 -> 15062500 | N3: PT001 | O3: =VLOOKUP(N3,'Master Kode'!$F$3:$G$9,2,0) -> PT Bintang Daur Ulang | P3: =SUMIF(F:F,O3,I:I) -> 74040 | Q3: =P3/$P$10 -> 0.092160621
B4: INV040125002 | C4: =DATE(2000+MID(B4,8,2),MID(B4,6,2),MID(B4,4,2)) -> 45661 | D4: DO040125002 | E4: PO01012502 | F4: PT Surya Polimer Indonesia | G4: BP002 | H4: =VLOOKUP(G4,'Master Kode'!$B$3:$D$13,2,0) -> PET Blue Flakes | I4: 3015 | J4: kg | K4: =VLOOKUP(G4,'Master Kode'!$B$3:$D$13,3,0) -> 10000 | L4: =K4*I4 -> 30150000 | N4: PT002 | O4: =VLOOKUP(N4,'Master Kode'!$F$3:$G$9,2,0) -> PT Cahaya Plastik Abadi | P4: =SUMIF(F:F,O4,I:I) -> 115275 | Q4: =P4/$P$10 -> 0.14348752
B5: INV050125003 | C5: =DATE(2000+MID(B5,8,2),MID(B5,6,2),MID(B5,4,2)) -> 45662 | D5: DO050125003 | E5: PO02012501 | F5: PT Mitra Plastik Nusantara | G5: BP003 | H5: =VLOOKUP(G5,'Master Kode'!$B$3:$D$13,2,0) -> HDPE Natural Flakes | I5: 2150 | J5: kg | K5: =VLOOKUP(G5,'Master Kode'!$B$3:$D$13,3,0) -> 13500 | L5: =K5*I5 -> 29025000 | N5: PT003 | O5: =VLOOKUP(N5,'Master Kode'!$F$3:$G$9,2,0) -> PT Global Recycle Industry | P5: =SUMIF(F:F,O5,I:I) -> 128865 | Q5: =P5/$P$10 -> 0.16040355
B6: INV050125004 | C6: =DATE(2000+MID(B6,8,2),MID(B6,6,2),MID(B6,4,2)) -> 45662 | D6: DO050125004 | E6: PO02012502 | F6: PT Global Recycle Industry | G6: BP004 | H6: =VLOOKUP(G6,'Master Kode'!$B$3:$D$13,2,0) -> HDPE Mixed Color Flakes | I6: 1890 | J6: kg | K6: =VLOOKUP(G6,'Master Kode'!$B$3:$D$13,3,0) -> 9500 | L6: =K6*I6 -> 17955000 | N6: PT004 | O6: =VLOOKUP(N6,'Master Kode'!$F$3:$G$9,2,0) -> PT Indo Plastik Mandiri | P6: =SUMIF(F:F,O6,I:I) -> 114210 | Q6: =P6/$P$10 -> 0.14216187
B7: INV060125005 | C7: =DATE(2000+MID(B7,8,2),MID(B7,6,2),MID(B7,4,2)) -> 45663 | D7: DO060125005 | E7: PO03012501 | F7: PT Indo Plastik Mandiri | G7: BP005 | H7: =VLOOKUP(G7,'Master Kode'!$B$3:$D$13,2,0) -> PP Injection Flakes | I7: 2750 | J7: kg | K7: =VLOOKUP(G7,'Master Kode'!$B$3:$D$13,3,0) -> 11000 | L7: =K7*I7 -> 30250000 | N7: PT005 | O7: =VLOOKUP(N7,'Master Kode'!$F$3:$G$9,2,0) -> PT Maju Jaya Plastik | P7: =SUMIF(F:F,O7,I:I) -> 123660 | Q7: =P7/$P$10 -> 0.15392467
B8: INV070125006 | C8: =DATE(2000+MID(B8,8,2),MID(B8,6,2),MID(B8,4,2)) -> 45664 | D8: DO070125006 | E8: PO03012502 | F8: PT Cahaya Plastik Abadi | G8: BP006 | H8: =VLOOKUP(G8,'Master Kode'!$B$3:$D$13,2,0) -> PET Green Flakes | I8: 3320 | J8: kg | K8: =VLOOKUP(G8,'Master Kode'!$B$3:$D$13,3,0) -> 9000 | L8: =K8*I8 -> 29880000 | N8: PT006 | O8: =VLOOKUP(N8,'Master Kode'!$F$3:$G$9,2,0) -> PT Mitra Plastik Nusantara | P8: =SUMIF(F:F,O8,I:I) -> 115385 | Q8: =P8/$P$10 -> 0.14362444
B9: INV070125007 | C9: =DATE(2000+MID(B9,8,2),MID(B9,6,2),MID(B9,4,2)) -> 45664 | D9: DO070125007 | E9: PO04012501 | F9: PT Bintang Daur Ulang | G9: BP007 | H9: =VLOOKUP(G9,'Master Kode'!$B$3:$D$13,2,0) -> HDPE Blue Drum Flakes | I9: 1450 | J9: kg | K9: =VLOOKUP(G9,'Master Kode'!$B$3:$D$13,3,0) -> 11500 | L9: =K9*I9 -> 16675000 | N9: PT007 | O9: =VLOOKUP(N9,'Master Kode'!$F$3:$G$9,2,0) -> PT Surya Polimer Indonesia | P9: =SUMIF(F:F,O9,I:I) -> 131945 | Q9: =P9/$P$10 -> 0.16423735
B10: INV080125008 | C10: =DATE(2000+MID(B10,8,2),MID(B10,6,2),MID(B10,4,2)) -> 45665 | D10: DO080125008 | E10: PO04012502 | F10: PT Maju Jaya Plastik | G10: BP008 | H10: =VLOOKUP(G10,'Master Kode'!$B$3:$D$13,2,0) -> PET Mixed Color Flakes | I10: 2100 | J10: kg | K10: =VLOOKUP(G10,'Master Kode'!$B$3:$D$13,3,0) -> 8500 | L10: =K10*I10 -> 17850000 | N10: Total | P10: =SUM(P3:P9) -> 803380 | Q10: =SUM(Q3:Q9) -> 1
B11: INV090125009 | C11: =DATE(2000+MID(B11,8,2),MID(B11,6,2),MID(B11,4,2)) -> 45666 | D11: DO090125009 | E11: PO05012501 | F11: PT Surya Polimer Indonesia | G11: BP009 | H11: =VLOOKUP(G11,'Master Kode'!$B$3:$D$13,2,0) -> PP White Flakes | I11: 3980 | J11: kg | K11: =VLOOKUP(G11,'Master Kode'!$B$3:$D$13,3,0) -> 12000 | L11: =K11*I11 -> 47760000
B12: INV100125010 | C12: =DATE(2000+MID(B12,8,2),MID(B12,6,2),MID(B12,4,2)) -> 45667 | D12: DO100125010 | E12: PO06012501 | F12: PT Mitra Plastik Nusantara | G12: BP010 | H12: =VLOOKUP(G12,'Master Kode'!$B$3:$D$13,2,0) -> HDPE Bottle Cap Flakes | I12: 2560 | J12: kg | K12: =VLOOKUP(G12,'Master Kode'!$B$3:$D$13,3,0) -> 10500 | L12: =K12*I12 -> 26880000
B13: INV110125011 | C13: =DATE(2000+MID(B13,8,2),MID(B13,6,2),MID(B13,4,2)) -> 45668 | D13: DO110125011 | E13: PO07012501 | F13: PT Global Recycle Industry | G13: BP011 | H13: =VLOOKUP(G13,'Master Kode'!$B$3:$D$13,2,0) -> PET Hot Washed Flakes | I13: 3175 | J13: kg | K13: =VLOOKUP(G13,'Master Kode'!$B$3:$D$13,3,0) -> 14500 | L13: =K13*I13 -> 46037500
B14: INV120125012 | C14: =DATE(2000+MID(B14,8,2),MID(B14,6,2),MID(B14,4,2)) -> 45669 | D14: DO120125012 | E14: PO08012501 | F14: PT Indo Plastik Mandiri | G14: BP001 | H14: =VLOOKUP(G14,'Master Kode'!$B$3:$D$13,2,0) -> PET Clear Flakes | I14: 1875 | J14: kg | K14: =VLOOKUP(G14,'Master Kode'!$B$3:$D$13,3,0) -> 12500 | L14: =K14*I14 -> 23437500
B15: INV130125013 | C15: =DATE(2000+MID(B15,8,2),MID(B15,6,2),MID(B15,4,2)) -> 45670 | D15: DO130125013 | E15: PO09012501 | F15: PT Cahaya Plastik Abadi | G15: BP002 | H15: =VLOOKUP(G15,'Master Kode'!$B$3:$D$13,2,0) -> PET Blue Flakes | I15: 2250 | J15: kg | K15: =VLOOKUP(G15,'Master Kode'!$B$3:$D$13,3,0) -> 10000 | L15: =K15*I15 -> 22500000
B16: INV140125014 | C16: =DATE(2000+MID(B16,8,2),MID(B16,6,2),MID(B16,4,2)) -> 45671 | D16: DO140125014 | E16: PO10012501 | F16: PT Bintang Daur Ulang | G16: BP003 | H16: =VLOOKUP(G16,'Master Kode'!$B$3:$D$13,2,0) -> HDPE Natural Flakes | I16: 1650 | J16: kg | K16: =VLOOKUP(G16,'Master Kode'!$B$3:$D$13,3,0) -> 13500 | L16: =K16*I16 -> 22275000
B17: INV150125015 | C17: =DATE(2000+MID(B17,8,2),MID(B17,6,2),MID(B17,4,2)) -> 45672 | D17: DO150125015 | E17: PO11012501 | F17: PT Maju Jaya Plastik | G17: BP004 | H17: =VLOOKUP(G17,'Master Kode'!$B$3:$D$13,2,0) -> HDPE Mixed Color Flakes | I17: 2890 | J17: kg | K17: =VLOOKUP(G17,'Master Kode'!$B$3:$D$13,3,0) -> 9500 | L17: =K17*I17 -> 27455000
B18: INV160125016 | C18: =DATE(2000+MID(B18,8,2),MID(B18,6,2),MID(B18,4,2)) -> 45673 | D18: DO160125016 | E18: PO12012501 | F18: PT Surya Polimer Indonesia | G18: BP005 | H18: =VLOOKUP(G18,'Master Kode'!$B$3:$D$13,2,0) -> PP Injection Flakes | I18: 3200 | J18: kg | K18: =VLOOKUP(G18,'Master Kode'!$B$3:$D$13,3,0) -> 11000 | L18: =K18*I18 -> 35200000
B19: INV170125017 | C19: =DATE(2000+MID(B19,8,2),MID(B19,6,2),MID(B19,4,2)) -> 45674 | D19: DO170125017 | E19: PO13012501 | F19: PT Mitra Plastik Nusantara | G19: BP006 | H19: =VLOOKUP(G19,'Master Kode'!$B$3:$D$13,2,0) -> PET Green Flakes | I19: 1425 | J19: kg | K19: =VLOOKUP(G19,'Master Kode'!$B$3:$D$13,3,0) -> 9000 | L19: =K19*I19 -> 12825000
B20: INV180125018 | C20: =DATE(2000+MID(B20,8,2),MID(B20,6,2),MID(B20,4,2)) -> 45675 | D20: DO180125018 | E20: PO14012501 | F20: PT Global Recycle Industry | G20: BP007 | H20: =VLOOKUP(G20,'Master Kode'!$B$3:$D$13,2,0) -> HDPE Blue Drum Flakes | I20: 2780 | J20: kg | K20: =VLOOKUP(G20,'Master Kode'!$B$3:$D$13,3,0) -> 11500 | L20: =K20*I20 -> 31970000
B21: INV190125019 | C21: =DATE(2000+MID(B21,8,2),MID(B21,6,2),MID(B21,4,2)) -> 45676 | D21: DO190125019 | E21: PO15012501 | F21: PT Indo Plastik Mandiri | G21: BP008 | H21: =VLOOKUP(G21,'Master Kode'!$B$3:$D$13,2,0) -> PET Mixed Color Flakes | I21: 3340 | J21: kg | K21: =VLOOKUP(G21,'Master Kode'!$B$3:$D$13,3,0) -> 8500 | L21: =K21*I21 -> 28390000
B22: INV200125020 | C22: =DATE(2000+MID(B22,8,2),MID(B22,6,2),MID(B22,4,2)) -> 45677 | D22: DO200125020 | E22: PO16012501 | F22: PT Cahaya Plastik Abadi | G22: BP009 | H22: =VLOOKUP(G22,'Master Kode'!$B$3:$D$13,2,0) -> PP White Flakes | I22: 2450 | J22: kg | K22: =VLOOKUP(G22,'Master Kode'!$B$3:$D$13,3,0) -> 12000 | L22: =K22*I22 -> 29400000
... B313: INV231225027 | C313: =DATE(2000+MID(B313,8,2),MID(B313,6,2),MID(B313,4,2)) -> 46014 | D313: DO231225027 | E313: PO20122501 | F313: PT Cahaya Plastik Abadi | G313: BP005 | H313: =VLOOKUP(G313,'Master Kode'!$B$3:$D$13,2,0) -> PP Injection Flakes | I313: 2750 | J313: kg | K313: =VLOOKUP(G313,'Master Kode'!$B$3:$D$13,3,0) -> 11000 | L313: =K313*I313 -> 30250000

Sheet Pivot Table
B2: Produk | C2: Total Qty | E2: Customer | F2: Total Qty | H2: Qty Product per Month | I2: Produk | V2: No Invoice | W2: Nama Barang | X2: Total (Rp) | Y2: Total (Juta) | AA2: Product | AB2: Total PO (Juta)
B3: HDPE Bottle Cap Flakes | C3: 30985 | E3: PT Bintang Daur Ulang | F3: 74040 | H3: Bulan | I3: HDPE Blue Drum Flakes | J3: HDPE Bottle Cap Flakes | K3: HDPE Mixed Color Flakes | L3: HDPE Natural Flakes | M3: PET Blue Flakes | N3: PET Clear Flakes | O3: PET Green Flakes | P3: PET Hot Washed Flakes | Q3: PET Mixed Color Flakes | R3: PP Injection Flakes | S3: PP White Flakes | T3: Grand Total | V3: INV030125001 | W3: PET Clear Flakes | X3: 15062500 | Y3: =X3/1000000 -> 15.0625 | AA3: HDPE Bottle Cap Flakes | AB3: 325.3425
B4: HDPE Blue Drum Flakes | C4: 42445 | E4: PT Cahaya Plastik Abadi | F4: 115275 | H4: Jan | I4: 4230 | J4: 4430 | K4: 4780 | L4: 5780 | M4: 7415 | N4: 3080 | O4: 4745 | P4: 6165 | Q4: 5440 | R4: 5950 | S4: 6430 | T4: 58445 | V4: INV040125002 | W4: PET Blue Flakes | X4: 30150000 | Y4: =X4/1000000 -> 30.15 | AA4: HDPE Blue Drum Flakes | AB4: 488.1175
B5: PP White Flakes | C5: 55530 | E5: PT Global Recycle Industry | F5: 128865 | H5: Feb | I5: 3175 | J5: 1600 | K5: 11500 | L5: 3630 | M5: 9250 | N5: 10330 | O5: 4800 | P5: 7450 | Q5: 6400 | R5: 5700 | S5: 5100 | T5: 68935 | V5: INV050125003 | W5: HDPE Natural Flakes | X5: 29025000 | Y5: =X5/1000000 -> 29.025 | AA5: PET Mixed Color Flakes | AB5: 594.1925
B6: PET Mixed Color Flakes | C6: 69905 | E6: PT Indo Plastik Mandiri | F6: 114210 | H6: Mar | I6: 3200 | K6: 7700 | L6: 6300 | M6: 8670 | N6: 7305 | O6: 6000 | P6: 6750 | Q6: 5300 | R6: 9000 | S6: 4380 | T6: 64605 | V6: INV050125004 | W6: HDPE Mixed Color Flakes | X6: 17955000 | Y6: =X6/1000000 -> 17.955 | AA6: PP White Flakes | AB6: 666.36
B7: PET Hot Washed Flakes | C7: 81500 | E7: PT Maju Jaya Plastik | F7: 123660 | H7: Apr | I7: 1650 | J7: 3750 | K7: 6180 | L7: 6420 | M7: 6735 | N7: 6790 | O7: 4640 | P7: 6560 | Q7: 5900 | R7: 8065 | S7: 5590 | T7: 62280 | V7: INV060125005 | W7: PP Injection Flakes | X7: 30250000 | Y7: =X7/1000000 -> 30.25 | AA7: PET Green Flakes | AB7: 770.13
B8: HDPE Natural Flakes | C8: 82685 | E8: PT Mitra Plastik Nusantara | F8: 115385 | H8: May | I8: 4080 | J8: 3885 | K8: 6310 | L8: 6460 | M8: 9550 | N8: 7390 | O8: 8245 | P8: 6045 | Q8: 7150 | R8: 9100 | T8: 68215 | V8: INV070125006 | W8: PET Green Flakes | X8: 29880000 | Y8: =X8/1000000 -> 29.88 | AA8: HDPE Mixed Color Flakes | AB8: 801.705
B9: HDPE Mixed Color Flakes | C9: 84390 | E9: PT Surya Polimer Indonesia | F9: 131945 | H9: Jun | I9: 5560 | K9: 9155 | L9: 6670 | M9: 5300 | N9: 6255 | O9: 9510 | P9: 7400 | Q9: 5870 | R9: 5370 | S9: 4880 | T9: 65970 | V9: INV070125007 | W9: HDPE Blue Drum Flakes | X9: 16675000 | Y9: =X9/1000000 -> 16.675 | AA9: PET Blue Flakes | AB9: 916.2
B10: PP Injection Flakes | C10: 85110 | E10: Grand Total | F10: 803380 | H10: Jul | I10: 2210 | J10: 4150 | K10: 6275 | L10: 9975 | M10: 9420 | N10: 7090 | O10: 9975 | P10: 5200 | Q10: 6020 | R10: 8075 | S10: 2950 | T10: 71340 | V10: INV080125008 | W10: PET Mixed Color Flakes | X10: 17850000 | Y10: =X10/1000000 -> 17.85 | AA10: PP Injection Flakes | AB10: 936.21
B11: PET Green Flakes | C11: 85570 | H11: Aug | I11: 3400 | J11: 5750 | K11: 3850 | L11: 6650 | M11: 6200 | N11: 7950 | O11: 8500 | P11: 6950 | Q11: 4500 | R11: 5850 | S11: 5900 | T11: 65500 | V11: INV090125009 | W11: PP White Flakes | X11: 47760000 | Y11: =X11/1000000 -> 47.76 | AA11: HDPE Natural Flakes | AB11: 1116.2475
B12: PET Blue Flakes | C12: 91620 | E12: Customer | F12: Total Purchase (Rp) | H12: Sep | I12: 3580 | J12: 1540 | K12: 8570 | L12: 8800 | M12: 7130 | N12: 8430 | O12: 9715 | P12: 8250 | Q12: 6200 | R12: 9100 | S12: 4600 | T12: 75915 | V12: INV100125010 | W12: HDPE Bottle Cap Flakes | X12: 26880000 | Y12: =X12/1000000 -> 26.88 | AA12: PET Clear Flakes | AB12: 1170.5
B13: PET Clear Flakes | C13: 93640 | E13: PT Bintang Daur Ulang | F13: 853877500 | H13: Oct | I13: 5220 | J13: 4210 | K13: 4960 | L13: 9450 | M13: 7190 | N13: 6770 | O13: 5380 | P13: 7060 | Q13: 4555 | R13: 4730 | S13: 6090 | T13: 65615 | V13: INV110125011 | W13: PET Hot Washed Flakes | X13: 46037500 | Y13: =X13/1000000 -> 46.0375 | AA13: PET Hot Washed Flakes | AB13: 1181.75
B14: Grand Total | C14: 803380 | E14: PT Cahaya Plastik Abadi | F14: 1243285000 | H14: Nov | I14: 3010 | J14: 1670 | K14: 6720 | L14: 6430 | M14: 5940 | N14: 9960 | O14: 7730 | P14: 7180 | Q14: 5910 | R14: 6090 | S14: 4640 | T14: 65280 | V14: INV120125012 | W14: PET Clear Flakes | X14: 23437500 | Y14: =X14/1000000 -> 23.4375 | AA14: Grand Total | AB14: 8966.755
E15: PT Global Recycle Industry | F15: 1393677500 | H15: Dec | I15: 3130 | K15: 8390 | L15: 6120 | M15: 8820 | N15: 12290 | O15: 6330 | P15: 6490 | Q15: 6660 | R15: 8080 | S15: 4970 | T15: 71280 | V15: INV130125013 | W15: PET Blue Flakes | X15: 22500000 | Y15: =X15/1000000 -> 22.5
B16: Produk | C16: Total Purchase (Rp) | E16: PT Indo Plastik Mandiri | F16: 1279122500 | H16: Grand Total | I16: 42445 | J16: 30985 | K16: 84390 | L16: 82685 | M16: 91620 | N16: 93640 | O16: 85570 | P16: 81500 | Q16: 69905 | R16: 85110 | S16: 55530 | T16: 803380 | V16: INV140125014 | W16: HDPE Natural Flakes | X16: 22275000 | Y16: =X16/1000000 -> 22.275
B17: HDPE Bottle Cap Flakes | C17: 325342500 | E17: PT Maju Jaya Plastik | F17: 1421545000 | V17: INV150125015 | W17: HDPE Mixed Color Flakes | X17: 27455000 | Y17: =X17/1000000 -> 27.455
B18: HDPE Blue Drum Flakes | C18: 488117500 | E18: PT Mitra Plastik Nusantara | F18: 1327135000 | H18: Total Product Purchase per Month | I18: Bulan | V18: INV160125016 | W18: PP Injection Flakes | X18: 35200000 | Y18: =X18/1000000 -> 35.2
B19: PET Mixed Color Flakes | C19: 594192500 | E19: PT Surya Polimer Indonesia | F19: 1448112500 | H19: Customer | I19: PT Bintang Daur Ulang | J19: PT Cahaya Plastik Abadi | K19: PT Global Recycle Industry | L19: PT Indo Plastik Mandiri | M19: PT Maju Jaya Plastik | N19: PT Mitra Plastik Nusantara | O19: PT Surya Polimer Indonesia | P19: Grand Total | V19: INV170125017 | W19: PET Green Flakes | X19: 12825000 | Y19: =X19/1000000 -> 12.825
B20: PP White Flakes | C20: 666360000 | E20: Grand Total | F20: 8966755000 | H20: Jan | I20: 4970 | J20: 8020 | K20: 7845 | L20: 7965 | M20: 9185 | N20: 8115 | O20: 12345 | P20: 58445 | V20: INV180125018 | W20: HDPE Blue Drum Flakes | X20: 31970000 | Y20: =X20/1000000 -> 31.97
B21: PET Green Flakes | C21: 770130000 | H21: Feb | I21: 5475 | J21: 6380 | K21: 16700 | L21: 11250 | M21: 8950 | N21: 8450 | O21: 11730 | P21: 68935 | V21: INV190125019 | W21: PET Mixed Color Flakes | X21: 28390000 | Y21: =X21/1000000 -> 28.39
B22: HDPE Mixed Color Flakes | C22: 801705000 | E22: Customer | F22: Persentase | H22: Mar | I22: 6250 | J22: 8400 | K22: 10055 | L22: 8220 | M22: 11350 | N22: 9450 | O22: 10880 | P22: 64605 | V22: INV200125020 | W22: PP White Flakes | X22: 29400000 | Y22: =X22/1000000 -> 29.4
B23: PET Blue Flakes | C23: 916200000 | E23: PT Bintang Daur Ulang | F23: 0.092160621 | H23: Apr | I23: 5505 | J23: 8480 | K23: 8160 | L23: 9940 | M23: 9390 | N23: 8835 | O23: 11970 | P23: 62280 | V23: INV220125021 | W23: HDPE Bottle Cap Flakes | X23: 19635000 | Y23: =X23/1000000 -> 19.635
B24: PP Injection Flakes | C24: 936210000 | E24: PT Cahaya Plastik Abadi | F24: 0.14348752 | H24: May | I24: 5720 | J24: 11880 | K24: 10440 | L24: 10360 | M24: 10600 | N24: 10155 | O24: 9060 | P24: 68215 | V24: INV240125022 | W24: PET Hot Washed Flakes | X24: 43355000 | Y24: =X24/1000000 -> 43.355
B25: HDPE Natural Flakes | C25: 1116247500 | E25: PT Global Recycle Industry | F25: 0.16040355 | H25: Jun | I25: 6560 | J25: 10060 | K25: 9640 | L25: 8470 | M25: 11020 | N25: 10800 | O25: 9420 | P25: 65970 | V25: INV260125023 | W25: PET Blue Flakes | X25: 21500000 | Y25: =X25/1000000 -> 21.5
B26: PET Clear Flakes | C26: 1170500000 | E26: PT Indo Plastik Mandiri | F26: 0.14216187 | H26: Jul | I26: 7960 | J26: 9410 | K26: 10625 | L26: 11025 | M26: 11650 | N26: 10830 | O26: 9840 | P26: 71340 | V26: INV290125024 | W26: HDPE Natural Flakes | X26: 26730000 | Y26: =X26/1000000 -> 26.73
B27: PET Hot Washed Flakes | C27: 1181750000 | E27: PT Maju Jaya Plastik | F27: 0.15392467 | H27: Aug | I27: 7200 | J27: 8550 | K27: 10300 | L27: 7300 | M27: 10550 | N27: 9550 | O27: 12050 | P27: 65500 | V27: INV010225001 | W27: HDPE Mixed Color Flakes | X27: 29450000 | Y27: =X27/1000000 -> 29.45
B28: Grand Total | C28: 8966755000 | E28: PT Mitra Plastik Nusantara | F28: 0.14362444 | H28: Sep | I28: 5120 | J28: 12815 | K28: 10800 | L28: 12930 | M28: 13260 | N28: 9100 | O28: 11890 | P28: 75915 | V28: INV030225002 | W28: PET Clear Flakes | X28: 30000000 | Y28: =X28/1000000 -> 30
E29: PT Surya Polimer Indonesia | F29: 0.16423735 | H29: Oct | I29: 7840 | J29: 8650 | K29: 12330 | L29: 6460 | M29: 10545 | N29: 10230 | O29: 9560 | P29: 65615 | V29: INV040225003 | W29: HDPE Natural Flakes | X29: 24975000 | Y29: =X29/1000000 -> 24.975
E30: Grand Total | F30: 1 | H30: Nov | I30: 4680 | J30: 11320 | K30: 12490 | L30: 8480 | M30: 6840 | N30: 10410 | O30: 11060 | P30: 65280 | V30: INV050225004 | W30: PET Blue Flakes | X30: 31500000 | Y30: =X30/1000000 -> 31.5
H31: Dec | I31: 6760 | J31: 11310 | K31: 9480 | L31: 11810 | M31: 10320 | N31: 9460 | O31: 12140 | P31: 71280 | V31: INV050225005 | W31: PP Injection Flakes | X31: 32450000 | Y31: =X31/1000000 -> 32.45
E32: Customer | F32: Total Qty (Kg) | H32: Grand Total | I32: 74040 | J32: 115275 | K32: 128865 | L32: 114210 | M32: 123660 | N32: 115385 | O32: 131945 | P32: 803380 | V32: INV060225006 | W32: PET Green Flakes | X32: 15300000 | Y32: =X32/1000000 -> 15.3
E33: PT Bintang Daur Ulang | F33: 74040 | V33: INV060225007 | W33: HDPE Mixed Color Flakes | X33: 25175000 | Y33: =X33/1000000 -> 25.175
E34: PT Cahaya Plastik Abadi | F34: 115275 | V34: INV070225008 | W34: HDPE Blue Drum Flakes | X34: 16387500 | Y34: =X34/1000000 -> 16.3875
E35: PT Global Recycle Industry | F35: 128865 | V35: INV070225009 | W35: PET Mixed Color Flakes | X35: 28475000 | Y35: =X35/1000000 -> 28.475
E36: PT Indo Plastik Mandiri | F36: 114210 | V36: INV080225010 | W36: PET Clear Flakes | X36: 26250000 | Y36: =X36/1000000 -> 26.25
E37: PT Maju Jaya Plastik | F37: 123660 | V37: INV080225011 | W37: PET Hot Washed Flakes | X37: 56550000 | Y37: =X37/1000000 -> 56.55
E38: PT Mitra Plastik Nusantara | F38: 115385 | V38: INV090225012 | W38: PP White Flakes | X38: 30000000 | Y38: =X38/1000000 -> 30
E39: PT Surya Polimer Indonesia | F39: 131945 | V39: INV090225013 | W39: HDPE Natural Flakes | X39: 24030000 | Y39: =X39/1000000 -> 24.03
E40: Grand Total | F40: 803380 | V40: INV100225014 | W40: PET Blue Flakes | X40: 32000000 | Y40: =X40/1000000 -> 32
V41: INV100225015 | W41: PET Clear Flakes | X41: 37250000 | Y41: =X41/1000000 -> 37.25
...
